Workbook

Sheet Employee Checklist (For IT)
A1: New Employee
A2: SETUP REQUEST CHECKLIST
A3: * One request per employee. Allow one to two weeks for complete setup of employee.
B4: Employee Name: | C4: ='Manager Setup'!C6 -> Jane Sharon Kim
B5: Branch/Dept: | C5: ='Manager Setup'!C7 -> SBA Note
B6: Title: | C6: ='Manager Setup'!C8 -> SBA Note Assistant
B7: Start Date: | C7: ='Manager Setup'!C9 -> 43832
B8: Requested by: | C8: ='Manager Setup'!C10 -> Debbie Lee | F8: Initial: | G8: ='Manager Setup'!H10 -> DL
B10: ITEMS | C10: USER ID or CONDITION/LEVEL/LOC | F10: ACTION TAKEN / ADDITIONAL INFO | J10: INITIAL
B11: Network ID | C11: janes.kim | F11: Created. PW, if not default: | J11: OK
B12: Distribution & Security Groups | C12: ps_sba | F12: Approval received | J12: OK
C13: See Page 3 for Access Rights and Approval
B14: E-mail Account | C14: Same name as network ID | F14: Created | J14: OK
B15: Personal Folder | C15: Same name as network ID | F15: Created | J15: OK
B16: Phone Number ext. | C16: 201-5423 | F16: Created | J16: OK
B17: Voicemail Box | C17: 5423 | F17: Created | J17: OK
B18: Fedline Advantage ID | C18: N/A | J18: PA
B19: Swift Axletree ID | C19: N/A | J19: PA
B20: DCI User ID/O Code | C20: janekim/40JS | F20: Created | J20: PA
C21: See Page 2 for Access Rights and Approval
B22: Deposit Pro/Laser Pro | F22: n/a | J22: TL
B23: User Master List | F23: Updated | J23: TL
B24: Kaseya Agent/Profile | C24: Configured profile | F24: Assigned | J24: TL
B25: Computer Name | C25: COMP NAME: PCB031 | F25: Assigned | J25: TL
B26: PC Inventory Update | C26: PC Allocation 2017-2018 & PC PCB naming inventory | F26: Updated | J26: TL
B27: Computer Location | C27: Refer to Seating Plan | F27: Updated | J27: TL
B28: Alarm Password | F28: Created | J28: JO
B29: Door Keycard | C29: Suite/Branch No.: | F29: Created | J29: JO
B30: Starter Sheet | C30: Account Info Added | F30: Created and delivered | J30: TL
C31: 43829
C32: Date Setup Process Started
C34: Signature: Scott Yi, IT Manager

Sheet Manager Setup
A1: New Employee
A2: SETUP REQUEST
A3: * One request per employee. Allow one to two weeks for complete setup of employee.
A5: HR Use Only
B6: Employee Name: | C6: Jane Sharon Kim
B7: Branch/Dept: | C7: SBA Note
B8: Title: | C8: SBA Note Assistant
B9: Start Date: | C9: 43832
B10: Requested by: | C10: Debbie Lee | G10: Initial: | H10: DL
A13: Manager Use
A14: If employee is located in HQ:
B15: Employee Room No.:
C16: E.g. Room 900
B17: Employee Seat Location:
C18: E.g. Between Jane Doe and John Doe
B20: Employee Hiring Status:
D21: PCB Employee
D22: Non-PCB Employee/Temporary/Consultant
E23: Termination Date:
F24: (Required for non-PCB employees.)
B26: Does the seat have a computer for the employee's use?
D27: Yes, the computer name is:
F28: E.g. PCB123, 02-ops-0123
D29: No
B31: Does the seat have a monitor, a keyboard, and a mouse for the employee's use?
D32: Yes
D33: No, it is missing: | E33: All
E34: Monitor
E35: Keyboard
E36: Mouse
A38: If employee is located outside of HQ:
B40: Employee Hiring Status:
D41: PCB Employee
D42: Non-PCB Employee/Temporary/Consultant
E43: Termination Date:
F44: (Required for non-PCB employees.)
B45: Computer Name:
C46: E.g. PCB123, 02-ops-0123, 01-teller-01, teller0101

Sheet Access - iCore & Prologue
A1: New Employee
A2: SETUP REQUEST CHECKLIST
A3: This form to be filled out by Dept/Branch Manager (or user authorized by Manager).
A4: * Additional approval may be required for certain requests.
A5: * Please email this form to the IT Dept at IT_ChecklistSetup@paccitybank.com or fax to 213-355-8853.
A7: EMPLOYEE NAME: | E7: ='Employee Checklist (For IT)'!C4 -> Jane Sharon Kim
C9: iCORE360 ACCESS RIGHTS | H9: Under your dept/branch or business function,
C10: Dept/Branch Security Group | H10: enter 'O' on the box(es) of user access rights requirements
C11: According to job position
C13: OPS/Branch Security Group | H13: Loan Security Group | L13: Other HQ Group
C14: Ops Teller | H14: Loan Officer | L14: BSA
C15: Ops New Account | H15: Loan Note Dept. | L15: BSA Manager
C16: Ops Officer | H16: Loan Note Dept. Manager | L16: Compliance
C17: Branch Manager | H17: Loan CLD Collection | L17: Compliance Manager
C18: Ops Admin | H18: Loan CLD Note | L18: E-Banking
C19: Ops Admin Officer | H19: Loan RMC Note | L19: E-Banking Manager
C20: Ops Admin Manager | H20: Loan RMC Note Manager | L20: Inter@ct Access
C21: Ops Admin Parameter | H21: Loan SBA Note | L21: Positive Pay
C22: Modify Check Number | H22: Loan SBA Note Manager | L22: IT
C23: Exceptions Check Return | H23: Credit Bank Field | L23: IT Manager
H24: Trade Finance | L24: iCore Administrator
C25: Accounting Security Group | L25: iCore Password Admin
C26: Accounting | H26: Special Permissions | L26: DSG Administrator
C27: Accounting Investment | H27: Employee Account Access | L27: HR
C28: Accounting Manager | H28: MTX/GL Posting | L28: Base
C29: Accounting GL Screen | H29: MTX Approval (Sub Application) | L29: Management
C30: Accounting Parameter | H30: Document Imaging (Loan Officers)
C31: Accounting Swap Account Maint
C33: List additional iCore360 access rights the user requires:
C39: PROLOGUE ACCESS RIGHTS | H39: Enter 'O' on the box(es) of user access rights requirements.
C40: Security Groups for Prologue
C41: According to job function
C43: Prologue Security Groups
C44: Accouting User
C45: Accounting Approver
C46: Administrator
A49: MANAGER NAME: | H49: SIGNATURE: | L49: DATE:

Sheet Access - Network & SOD
A1: New Employee
A2: SETUP REQUEST CHECKLIST
A3: This form to be filled out by Dept/Branch Manager (or user authorized by Manager).
A4: * Additional approval may be required for certain requests.
A5: * Please email this form to the IT Dept at IT_ChecklistSetup@paccitybank.com or fax to 213-355-8853.
A7: EMPLOYEE NAME: | D7: ='Employee Checklist (For IT)'!C4 -> Jane Sharon Kim
B10: NETWORK ACCESS RIGHTS | F10: EMAIL DISTRIBUTION GROUPS
B12: Employee will be given the following network access: | F12: Employee will be added to the following distribution groups:
B13: Personal/Data/Branch/Dept. Drives: | F13: AA_All
B14: (H / M / L / P Drives) | F14: AA_All_Without_LPOs
B15: For Branch Only - (Y Drive) | F15: AA_(Department/Branch)
B16: Network Folder Based on Job Function | F16: AA_(Location/Functions)
B18: List additional network access rights and email distribution groups the user requires:
B24: SEGREGATION OF DUTIES MATRIX
B25: Please review the Segregation of Duties Matrix and ensure that the user's responsibilities and access rights do not conflict with any of the Segregation of Duties items. In addition, please describe any other Segregation of Duties items you would like to add.
B27: Check the box below to confirm you have reviewed the Segregation of Duties Matrix.
B29: I have reviewed the Segregation of Duties Matrix.
A31: MANAGER NAME: | C31: =IF('Access - iCore & Prologue'!D49="","",'Access - iCore & Prologue'!D49) | E31: SIGNATURE: | I31: DATE: | J31: =IF('Access - iCore & Prologue'!M49="","",'Access - iCore & Prologue'!M49)

Sheet Access - BSA
A1: New Employee
A2: SETUP REQUEST CHECKLIST
A3: This form to be filled out by the appropriate application process owner.
A4: * Additional approval may be required for certain requests.
A5: * Please email this form to the IT Dept at IT_ChecklistSetup@paccitybank.com or fax to 213-355-8853.
A7: EMPLOYEE NAME: | E7: ='Employee Checklist (For IT)'!C4 -> Jane Sharon Kim
B10: For access to BAM+, BSA Manager, or MIL, please complete the checklist below.
B11: Enter 'O' in the box(es) of access rights the user requires. Only 1 box can be marked under each role.
C13: Security Role | G13: Scenarios | M13: SAR Manager
C14: Administrator | G14: BSA Administrator | M14: Administrator
C15: Read Only | G15: BSA Read Only | M15: Administrator - Own SARs
C16: User | G16: BSA Supervisor | M16: Prepare
C17: Alert | G17: BSA User | M17: Prepare - Own SARs
C18: BSA Administrator | G18: IT User | M18: Prepare/Release
C19: BSA Read Only | G19: Universal Administrator | M19: Prepare/Release - Own SARs
C20: BSA Supervisor | G20: Task | M20: Prepare/Review
C21: BSA User | G21: Administrator | M21: Prepare/Review - Own SARs
C22: IT User | G22: BSA Supervisor | M22: Prepare/Review/Release
C23: Univesal Administrator | G23: BSA User | M23: Prepare/Review/Release - Own SARs
C24: Audit Log | G24: IT User | M24: Release
... C31: BSA Read Only | G31: Branch Mgr - Global Teller | M31: View Only - Own SARs
C32: BSA Supervisor | G32: Branch Mgr - Institution Teller
C33: BSA User | G33: Branch Supervisor | L33: List additional BAM+, BSA Manager, or MIL
C34: IT User | G34: BSA Clerk | L34: access rights the user requires:
C35: Universal Administrator | G35: BSA Officer
C36: Data Management | G36: BSA Officer Read Only
C37: Universal Administrator | G37: Report Writer
G38: Teller (MIL)
G39: Wire User
B43: For access to BSA Admin or BSA Navigator please complete the checklist below.
B44: Enter 'O' in the box(es) of access rights the user requires. Only 1 box can be marked under each role.
C46: BSA Navigator General | I46: Administrative Functions | M46: View Reports
C47: View CTRs (edit capability) | I47: Account | M47: CTR
C48: View CTRs (no edit capability) | I48: Affiliated Banks | M48: Suspect
C49: Delete Transaction Data | I49: Branch | M49: SAR
C50: Create CTR | I50: People | M50: Exempt
C51: Import Transactions | I51: System Control | M51: Administration
C52: File Electronic CTRs | I52: User
C53: Exempt Account Manintenance
C54: Suspect Reports Maintenance | I54: Notes | M54: Risk Evaluator
...

Sheet Application Checklist - For MGR
A1: New Employee
A2: SETUP REQUEST CHECKLIST
A4: EMPLOYEE NAME: | E4: ='Employee Checklist (For IT)'!C4 -> Jane Sharon Kim
A7: USER APPLICATIONS | E7: Enter 'O' on the box(es) of applications the user requires.
E8: User will be given standard access rights unless otherwise specified.
B10: Adobe Reader DC | F10: DCI Check Image | J10: Tsoft
B11: iCore360 | F11: VC Transaction | J11: Moody's Risk Analyst
B12: Microsoft Office | F12: Digital Insight Admin | J12: Prologue - Access Request Req.
B13: Deposit Pro | F13: RDC Check Review | J13: Stock Informatics
B14: Laser Pro | F14: MDC Check Review | J14: Report Informatics
B15: General System Setup(GSS) | F15: Cash Management Admin | J15: Call Reporter Premier
B16: DCI Teller | F16: Wire Automation | J16: Y9 Reporter Premier
B17: BSA Navigator | F17: eFunds | J17: FASB Infra 2
B18: BSA Manager | F18: Swift | J18: E-Reports (Ops Admin)
B19: BAM+ | F19: Wire Pro | J19: Lender's Office (RMC)
B20: Teller (MIL) | F20: Fedline Advantage | J20: Doc Magic (RMC)
B21: P21 Viewer | F21: Foxit PhantomPDF/ | J21: Lexis Nexis
B22: P21 Delete Function | F22: Adobe Acrobat DC | J22: Vining Sparks
F23: Infosight | J23: ASV
F24: Infosight - Training Guide | J24: EDD Tracking Manager
F25: TeamViewer | J25: Experian
A27: List other applications the user requires:
A31: MANAGER NAME: | C31: =IF('Access - iCore & Prologue'!D49="","",'Access - iCore & Prologue'!D49) | F31: SIGNATURE: | K31: DATE: | L31: =IF('Access - iCore & Prologue'!M49="","",'Access - iCore & Prologue'!M49)

Sheet iCore Security Legend
A1: iCore360
A2: ACCESS RIGHTS DESCRIPTIONS
A4: OPS/BRANCH SECURITY GROUP | B4: DESCRIPTION
A5: Ops Teller | B5: Access for Teller function
A6: Ops New Account | B6: Access to New Account / Customer Service function Includes access to Ops Teller
A7: Ops Officer | B7: Access to Ops Officer function Includes access to Ops New Account
A8: Branch Manager | B8: Access to Branch Manager function Includes access to Ops Officer group
A9: Ops Admin | B9: Access to Ops Admin function Includes access to Ops Officer group
A10: Ops Admin Officer | B10: Access to Ops Admin Officer function Includes access to Ops Admin group
A11: Ops Admin Manager | B11: Access to Ops Admin Manager function Includes access to Ops Admin group
A12: Ops Admin Parameter | B12: Full access to Deposit Parameters
A13: Modify Check Number | B13: Access to modify check number in deposit history
A14: Exceptions Check Return | B14: Access to process exception items
A16: ACCOUNTING SECURITY GROUP | B16: DESCRIPTION
... A59: Management | B59: Access to Management function

Sheet Prologue Security Legend
A1: Prologue
A2: ACCESS RIGHTS DESCRIPTIONS
A4: SECURITY GROUP | B4: DESCRIPTION
A5: Accounting User | B5: User can create transactions for GL and Fixed Assets modules but not approve transactions.
A6: Accounting Approver | B6: User cannot create transactions for GL and Fixed Assets modules but can approve transactions.
A7: Administrator | B7: Prologue user administrator. Cannot create or approve transactions.

Sheet Segregation of Duties Matrix
B2: Pacific City Bank Segregation of Duties Matrix Last Update: February 2019 Directions: A box with an 'X' means that both of the functions correlating with that box cannot be given to a single user. | D2: =C4 -> Network/System Admin | E2: =C5 -> Core System Admin | F2: =C6 -> Information Security Officer | G2: =C7 -> Fedline EUAC | H2: =C8 -> Fedline User | I2: =C9 -> Core System Transaction User | J2: =C10 -> Axletree (SWIFT) admin | K2: =C11 -> Axletree (SWIFT) User | L2: =C12 -> Access Rights Change Performer | M2: =C13 -> Access Rights Change Log Reviewer | N2: =C14 -> Prologue Admin | O2: =C15 -> Prologue User | P2: =C16 -> BSA Manager Admin | Q2: =C17 -> BSA Manager User | R2: =C18 -> BSA Admin (Navigator) Admin | S2: =C19 -> BSA Admin (Navigator) User | T2: =C20 -> FASBInfra Admin | U2: =C21 -> FASBInfra User | V2: =C22 -> ADP Master | W2: =C23 -> ADP Admin | X2: =C24 -> ADP User | Y2: =C25 -> Prologue Accounts Payable - check creator | Z2: =C26 -> Prologue Accounts Payable - check signer | AA2: =C27 -> Prologue GL Module - transaction creator | AB2: =C28 -> Prologue GL Module - transaction approver | AC2: =C29 -> Prologue Fixed Assets - transaction creator | AD2: =C30 -> Prologue Fixed Assets - transaction approver | AE2: =C31 -> iCore360 MTX entry | AF2: =C32 -> iCore360 MTX approver | AG2: =C33 -> Journal entries to GL poster | AH2: =C34 -> Journal entries callback | AI2: =C35 -> ADP Payroll Entry | AJ2: =C36 -> ADP Payroll Approver | AK2: =C37 -> 401k Entry/Preparer | AL2: =C38 -> 401k Approver | AM2: =C39 -> CTR E-File Preparer | AN2: =C40 -> CTR E-File Approver | AO2: =C41 -> SAR E-File Preparer | AP2: =C42 -> SAR E-File Approver | AQ2: =C43 -> New Account Review Reviewer | AR2: =C44 -> New Account Review Approver | AS2: =C45 -> Enhanced Due Diligence Reviewer | AT2: =C46 -> Enhanced Due Diligence Approver | AU2: =C47 -> FinCEN 314(a) Reviewer | AV2: =C48 -> FinCEN 314(a) Approver | AW2: =C49 -> Transaction Monitoring Alert Reviewer | AX2: =C50 -> Transaction Monitoring Case Reviewer | AY2: =C51 -> Wire Entry | AZ2: =C52 -> Wire Approval | BA2: =C53 -> MTX Entry | BB2: =C54 -> MTX Approval | BC2: =C55 -> Teller Capture User | BD2: =C56 -> Teller Capture File Modify and Delete | BE2: =C57 -> Exception Item Entry | BF2: =C58 -> Exception Item Approval | BG2: =C59 -> Dormant Account Maintenance | BH2: =C60 -> Dormant Account Callback Reviewer | BI2: =C61 -> Loan Officer | BJ2: =C62 -> Loan Account Transaction Performer | BK2: =C63 -> Loan Funding Requester | BL2: =C64 -> Loan Funding Approver
D3: 1 | E3: 2 | F3: 3 | G3: 4 | H3: 5 | I3: 6 | J3: 7 | K3: 8 | L3: 9 | M3: 10 | N3: 11 | O3: 12 | P3: 13 | Q3: 14 | R3: 15 | S3: 16 | T3: 17 | U3: 18 | V3: 19 | W3: 20 | X3: 21 | Y3: 22 | Z3: 23 | AA3: 24 | AB3: 25 | AC3: 26 | AD3: 27 | AE3: 28 | AF3: 29 | AG3: 30 | AH3: 31 | AI3: 32 | AJ3: 33 | AK3: 34 | AL3: 35 | AM3: 36 | AN3: 37 | AO3: 38 | AP3: 39 | AQ3: 40 | AR3: 41 | AS3: 42 | AT3: 43 | AU3: 44 | AV3: 45 | AW3: 46 | AX3: 47 | AY3: 48 | AZ3: 49 | BA3: 50 | BB3: 51 | BC3: 52 | BD3: 53 | BE3: 54 | BF3: 55 | BG3: 56 | BH3: 57 | BI3: 58 | BJ3: 59 | BK3: 60 | BL3: 61
B4: 1 | C4: Network/System Admin | E4: X | F4: X | H4: X | I4: X | K4: X
B5: 2 | C5: Core System Admin | D5: X | F5: X | H5: X | I5: X | K5: X | AE5: X | AF5: X | AG5: X | AH5: X | BH5: X | BJ5: X
B6: 3 | C6: Information Security Officer | D6: X | E6: X | G6: X | H6: X | I6: X | J6: X | K6: X | N6: X | O6: X | P6: X | Q6: X | R6: X | S6: X | T6: X | U6: X
B7: 4 | C7: Fedline EUAC | F7: X | H7: X
B8: 5 | C8: Fedline User | D8: X | E8: X | F8: X | G8: X
B9: 6 | C9: Core System Transaction User | D9: X | E9: X | F9: X
B10: 7 | C10: Axletree (SWIFT) admin | F10: X | K10: X
B11: 8 | C11: Axletree (SWIFT) User | D11: X | E11: X | F11: X | J11: X
B12: 9 | C12: Access Rights Change Performer | M12: X
B13: 10 | C13: Access Rights Change Log Reviewer | L13: X
B14: 11 | C14: Prologue Admin | F14: X | O14: X
B15: 12 | C15: Prologue User | F15: X | N15: X
B16: 13 | C16: BSA Manager Admin | F16: X | Q16: X
B17: 14 | C17: BSA Manager User | F17: X | P17: X
B18: 15 | C18: BSA Admin (Navigator) Admin | F18: X | S18: X
B19: 16 | C19: BSA Admin (Navigator) User | F19: X | R19: X
B20: 17 | C20: FASBInfra Admin | F20: X | U20: X
B21: 18 | C21: FASBInfra User | F21: X | T21: X
B22: 19 | C22: ADP Master | W22: X | X22: X
B23: 20 | C23: ADP Admin | V23: X | X23: X
B24: 21 | C24: ADP User | V24: X | W24: X
B25: 22 | C25: Prologue Accounts Payable - check creator | Z25: X
B26: 23 | C26: Prologue Accounts Payable - check signer | Y26: X
B27: 24 | C27: Prologue GL Module - transaction creator | AB27: X
B28: 25 | C28: Prologue GL Module - transaction approver | AA28: X
B29: 26 | C29: Prologue Fixed Assets - transaction creator | AD29: X
B30: 27 | C30: Prologue Fixed Assets - transaction approver | AC30: X
B31: 28 | C31: iCore360 MTX entry | E31: X | AF31: X
B32: 29 | C32: iCore360 MTX approver | E32: X | AE32: X
B33: 30 | C33: Journal entries to GL poster | E33: X | AH33: X
B34: 31 | C34: Journal entries callback | E34: X | AG34: X
B35: 32 | C35: ADP Payroll Entry | AJ35: X
B36: 33 | C36: ADP Payroll Approver | AI36: X
B37: 34 | C37: 401k Entry/Preparer | AL37: X
B38: 35 | C38: 401k Approver | AK38: X
B39: 36 | C39: CTR E-File Preparer | AN39: X
B40: 37 | C40: CTR E-File Approver | AM40: X
B41: 38 | C41: SAR E-File Preparer | AP41: X
...
